2022-06-19 01:37:17,137 : ERROR - logger.py - {'level': 'debug', 'msg': 'Full Traceback (most recent call last):\n  File "/usr/local/lib/python3.9/site-packages/snakemake/__init__.py", line 726, in snakemake\n    success = workflow.execute(\n  File "/usr/local/lib/python3.9/site-packages/snakemake/workflow.py", line 976, in execute\n    dag.create_conda_envs(\n  File "/usr/local/lib/python3.9/site-packages/snakemake/dag.py", line 313, in create_conda_envs\n    env.create(dryrun)\n  File "/usr/local/lib/python3.9/site-packages/snakemake/deployment/conda.py", line 391, in create\n    pin_file = self.pin_file\n  File "/usr/local/lib/python3.9/site-packages/snakemake/common/__init__.py", line 192, in __get__\n    value = self.method(instance)\n  File "/usr/local/lib/python3.9/site-packages/snakemake/deployment/conda.py", line 107, in pin_file\n    f".{self.conda.platform}.pin.txt"\n  File "/usr/local/lib/python3.9/site-packages/snakemake/common/__init__.py", line 192, in __get__\n    value = self.method(instance)\n  File "/usr/local/lib/python3.9/site-packages/snakemake/deployment/conda.py", line 102, in conda\n    return Conda(self._container_img)\n  File "/usr/local/lib/python3.9/site-packages/snakemake/deployment/conda.py", line 648, in __init__\n    shell.check_output(\n  File "/usr/local/lib/python3.9/site-packages/snakemake/shell.py", line 63, in check_output\n    return sp.check_output(cmd, shell=True, executable=executable, **kwargs)\n  File "/usr/local/lib/python3.9/subprocess.py", line 424, in check_output\n    return run(*popenargs, stdout=PIPE, timeout=timeout, check=True,\n  File "/usr/local/lib/python3.9/subprocess.py", line 528, in run\n    raise CalledProcessError(retcode, process.args,\nsubprocess.CalledProcessError: Command \'conda info --json\' returned non-zero exit status 127.\n', 'timestamp': 1655570237.1370182}
